2023-12-20 16:19:08,312 - INFO - main.py:5 - Bot started!
2023-12-20 17:18:52,117 - INFO - api_call.py:29 - API POST request for projects failed with error 400 Client Error: Bad Request for url: https://dqpllfj7tb.execute-api.us-east-1.amazonaws.com/dev/projects
2023-12-20 18:52:08,997 - INFO - main.py:6 - Bot started!
2023-12-20 18:52:27,007 - INFO - main.py:6 - Bot started!
2023-12-20 18:55:01,320 - INFO - main.py:6 - Bot started!
2023-12-20 19:14:05,275 - INFO - main.py:6 - Bot started!
2023-12-20 19:34:02,283 - INFO - main.py:6 - Bot started!
2023-12-20 19:44:44,807 - INFO - main.py:6 - Bot started!
2023-12-20 19:49:29,258 - INFO - main.py:6 - Bot started!
2023-12-20 19:50:27,270 - WARNING - main.py:9 - Update "{'message': {'new_chat_photo': [], 'new_chat_members': [], 'date': 1703101827, 'chat': {'type': 'private', 'username': 'realtalishaw', 'first_name': 'Talisha', 'id': 5915765775, 'last_name': 'White'}, 'entities': [], 'photo': [], 'delete_chat_photo': False, 'group_chat_created': False, 'message_id': 64, 'channel_chat_created': False, 'text': '07-20-1993', 'caption_entities': [], 'supergroup_chat_created': False, 'from': {'first_name': 'Talisha', 'last_name': 'White', 'id': 5915765775, 'language_code': 'en', 'is_bot': False, 'username': 'realtalishaw'}}, 'update_id': 978925644}" caused error "Object of type File is not JSON serializable"
2023-12-20 19:52:50,644 - INFO - main.py:6 - Bot started!
2023-12-21 00:50:06,868 - INFO - main.py:6 - Bot started!
2023-12-21 01:27:09,301 - INFO - main.py:6 - Bot started!
2023-12-21 01:39:40,342 - INFO - main.py:6 - Bot started!
2023-12-21 01:40:22,427 - WARNING - main.py:9 - Update "{'callback_query': {'id': '6961276460918830911', 'data': 'yes', 'message': {'new_chat_photo': [], 'new_chat_members': [], 'reply_markup': {'inline_keyboard': [[{'text': 'Yes', 'callback_data': 'yes'}, {'text': 'No', 'callback_data': 'no'}]]}, 'photo': [], 'channel_chat_created': False, 'chat': {'username': 'realtalishaw', 'id': 5915765775, 'last_name': 'White', 'first_name': 'Talisha', 'type': 'private'}, 'text': 'Is this information correct?', 'entities': [], 'message_id': 119, 'date': 1703122819, 'supergroup_chat_created': False, 'group_chat_created': False, 'delete_chat_photo': False, 'caption_entities': [], 'from': {'username': 'theometricsbot', 'is_bot': True, 'id': 6887127186, 'first_name': 'TheoBot'}}, 'chat_instance': '-3241866149608258687', 'from': {'language_code': 'en', 'username': 'realtalishaw', 'is_bot': False, 'id': 5915765775, 'last_name': 'White', 'first_name': 'Talisha'}}, 'update_id': 978925677}" caused error "'NoneType' object has no attribute 'reply_text'"
2023-12-21 01:42:07,410 - INFO - main.py:6 - Bot started!
2023-12-21 01:44:08,849 - WARNING - main.py:9 - Update "{'callback_query': {'chat_instance': '-3241866149608258687', 'message': {'entities': [], 'text': 'Is this information correct?', 'new_chat_members': [], 'delete_chat_photo': False, 'chat': {'first_name': 'Talisha', 'username': 'realtalishaw', 'last_name': 'White', 'id': 5915765775, 'type': 'private'}, 'new_chat_photo': [], 'supergroup_chat_created': False, 'group_chat_created': False, 'date': 1703123045, 'photo': [], 'channel_chat_created': False, 'message_id': 135, 'reply_markup': {'inline_keyboard': [[{'text': 'Yes', 'callback_data': 'yes'}, {'text': 'No', 'callback_data': 'no'}]]}, 'caption_entities': [], 'from': {'username': 'theometricsbot', 'id': 6887127186, 'is_bot': True, 'first_name': 'TheoBot'}}, 'id': '6961276463880568813', 'data': 'yes', 'from': {'username': 'realtalishaw', 'language_code': 'en', 'last_name': 'White', 'id': 5915765775, 'is_bot': False, 'first_name': 'Talisha'}}, 'update_id': 978925686}" caused error "'NoneType' object has no attribute 'reply_text'"
2023-12-21 02:18:19,900 - INFO - main.py:6 - Bot started!
2023-12-21 02:20:01,421 - WARNING - main.py:9 - Update "{'update_id': 978925695, 'callback_query': {'id': '6961276464358990833', 'chat_instance': '-3241866149608258687', 'data': 'yes', 'message': {'photo': [], 'new_chat_photo': [], 'date': 1703125198, 'chat': {'last_name': 'White', 'id': 5915765775, 'first_name': 'Talisha', 'username': 'realtalishaw', 'type': 'private'}, 'reply_markup': {'inline_keyboard': [[{'callback_data': 'yes', 'text': 'Yes'}, {'callback_data': 'no', 'text': 'No'}]]}, 'delete_chat_photo': False, 'group_chat_created': False, 'new_chat_members': [], 'text': 'Is this information correct?', 'supergroup_chat_created': False, 'message_id': 152, 'caption_entities': [], 'channel_chat_created': False, 'entities': [], 'from': {'id': 6887127186, 'is_bot': True, 'first_name': 'TheoBot', 'username': 'theometricsbot'}}, 'from': {'id': 5915765775, 'language_code': 'en', 'is_bot': False, 'first_name': 'Talisha', 'last_name': 'White', 'username': 'realtalishaw'}}}" caused error "'NoneType' object has no attribute 'reply_text'"
2023-12-21 02:23:55,336 - INFO - main.py:6 - Bot started!
2023-12-21 02:25:19,337 - WARNING - main.py:9 - Update "{'update_id': 978925705, 'callback_query': {'id': '6961276461351290659', 'data': 'yes', 'chat_instance': '-3241866149608258687', 'message': {'group_chat_created': False, 'caption_entities': [], 'message_id': 170, 'date': 1703125515, 'entities': [], 'new_chat_members': [], 'delete_chat_photo': False, 'text': 'Is this information correct?', 'photo': [], 'new_chat_photo': [], 'chat': {'id': 5915765775, 'first_name': 'Talisha', 'username': 'realtalishaw', 'last_name': 'White', 'type': 'private'}, 'supergroup_chat_created': False, 'channel_chat_created': False, 'reply_markup': {'inline_keyboard': [[{'callback_data': 'yes', 'text': 'Yes'}, {'callback_data': 'no', 'text': 'No'}]]}, 'from': {'username': 'theometricsbot', 'id': 6887127186, 'is_bot': True, 'first_name': 'TheoBot'}}, 'from': {'username': 'realtalishaw', 'id': 5915765775, 'last_name': 'White', 'language_code': 'en', 'is_bot': False, 'first_name': 'Talisha'}}}" caused error "'NoneType' object has no attribute 'reply_text'"
2023-12-21 02:27:33,145 - INFO - main.py:6 - Bot started!
2023-12-21 02:27:57,181 - INFO - main.py:6 - Bot started!
2023-12-21 02:28:16,873 - INFO - main.py:6 - Bot started!
2023-12-21 02:31:10,500 - INFO - main.py:6 - Bot started!
2023-12-21 03:01:13,476 - INFO - main.py:7 - Bot started!
2023-12-21 03:02:44,665 - INFO - main.py:7 - Bot started!
2023-12-21 03:05:31,598 - WARNING - main.py:10 - Update "{'update_id': 978925717, 'message': {'message_id': 193, 'date': 1703127931, 'supergroup_chat_created': False, 'chat': {'first_name': 'Talisha', 'type': 'private', 'last_name': 'White', 'id': 5915765775, 'username': 'realtalishaw'}, 'delete_chat_photo': False, 'new_chat_photo': [], 'text': '/register', 'entities': [{'offset': 0, 'length': 9, 'type': 'bot_command'}], 'caption_entities': [], 'photo': [], 'group_chat_created': False, 'channel_chat_created': False, 'new_chat_members': [], 'from': {'first_name': 'Talisha', 'id': 5915765775, 'username': 'realtalishaw', 'language_code': 'en', 'is_bot': False, 'last_name': 'White'}}}" caused error "name 'InlineKeyboardButton' is not defined"
2023-12-21 03:05:42,745 - WARNING - main.py:10 - Update "{'update_id': 978925720, 'message': {'message_id': 198, 'date': 1703127942, 'supergroup_chat_created': False, 'chat': {'first_name': 'Talisha', 'type': 'private', 'last_name': 'White', 'id': 5915765775, 'username': 'realtalishaw'}, 'delete_chat_photo': False, 'new_chat_photo': [], 'text': '/register', 'entities': [{'offset': 0, 'length': 9, 'type': 'bot_command'}], 'caption_entities': [], 'photo': [], 'group_chat_created': False, 'channel_chat_created': False, 'new_chat_members': [], 'from': {'first_name': 'Talisha', 'id': 5915765775, 'username': 'realtalishaw', 'language_code': 'en', 'is_bot': False, 'last_name': 'White'}}}" caused error "name 'InlineKeyboardButton' is not defined"
2023-12-21 03:27:28,851 - INFO - main.py:7 - Bot started!
2023-12-21 03:31:52,847 - INFO - main.py:7 - Bot started!
2023-12-21 03:36:41,479 - WARNING - main.py:10 - Update "None" caused error "Conflict: terminated by other getUpdates request; make sure that only one bot instance is running"
2023-12-21 03:36:46,723 - WARNING - main.py:10 - Update "None" caused error "Conflict: terminated by other getUpdates request; make sure that only one bot instance is running"
2023-12-21 03:49:44,579 - INFO - main.py:7 - Bot started!
2023-12-21 03:50:33,559 - INFO - main.py:7 - Bot started!
2023-12-21 12:46:16,741 - INFO - main.py:7 - Bot started!
2023-12-21 12:47:13,725 - INFO - user.py:15 - API Request, create_user
2023-12-21 12:47:16,027 - INFO - api_call.py:29 - API POST request for users failed with error 400 Client Error: Bad Request for url: https://dqpllfj7tb.execute-api.us-east-1.amazonaws.com/dev/users
2023-12-21 13:13:56,136 - INFO - main.py:7 - Bot started!
2023-12-21 13:16:00,942 - INFO - main.py:7 - Bot started!
2023-12-21 13:16:29,632 - INFO - main.py:7 - Bot started!
2023-12-21 13:17:37,172 - INFO - main.py:7 - Bot started!
2023-12-21 13:17:54,207 - INFO - main.py:7 - Bot started!
2023-12-21 13:22:06,374 - INFO - main.py:7 - Bot started!
2023-12-21 13:29:05,882 - INFO - main.py:7 - Bot started!
2023-12-21 13:34:03,037 - INFO - main.py:7 - Bot started!
2023-12-21 13:41:59,006 - INFO - main.py:7 - Bot started!
2023-12-21 13:42:42,664 - WARNING - main.py:10 - Update "{'callback_query': {'id': '6961276461156957982', 'chat_instance': '-3241866149608258687', 'data': 'proceed_to_quiz', 'message': {'chat': {'id': 5915765775, 'last_name': 'White', 'first_name': 'Talisha', 'type': 'private', 'username': 'realtalishaw'}, 'new_chat_photo': [], 'reply_markup': {'inline_keyboard': [[{'text': "I've watched the video, proceed to the quiz", 'callback_data': 'proceed_to_quiz'}]]}, 'photo': [], 'channel_chat_created': False, 'supergroup_chat_created': False, 'caption_entities': [], 'message_id': 852, 'text': "Click the button when you're ready to proceed to the quiz.", 'new_chat_members': [], 'date': 1703166161, 'entities': [], 'delete_chat_photo': False, 'group_chat_created': False, 'from': {'username': 'theometricsbot', 'is_bot': True, 'id': 6887127186, 'first_name': 'TheoBot'}}, 'from': {'username': 'realtalishaw', 'language_code': 'en', 'is_bot': False, 'id': 5915765775, 'last_name': 'White', 'first_name': 'Talisha'}}, 'update_id': 978926085}" caused error "name 'VIDEO' is not defined"
2023-12-21 13:44:57,033 - INFO - main.py:7 - Bot started!
2023-12-21 13:49:30,658 - INFO - main.py:7 - Bot started!
2023-12-21 14:06:18,373 - INFO - main.py:7 - Bot started!
2023-12-21 14:07:22,878 - INFO - onboarding.py:204 - Sending quiz: What is the capital of France?
2023-12-21 14:07:23,151 - INFO - onboarding.py:207 - Quiz sent, waiting for response...
2023-12-21 14:08:42,733 - INFO - main.py:7 - Bot started!
2023-12-21 14:09:42,601 - INFO - onboarding.py:204 - Sending quiz: What is the capital of France?
2023-12-21 14:09:42,882 - INFO - onboarding.py:207 - Quiz sent, waiting for response...
2023-12-21 14:13:08,921 - INFO - main.py:7 - Bot started!
2023-12-21 14:14:10,923 - INFO - onboarding.py:204 - Sending quiz: What is the capital of France?
2023-12-21 14:14:11,197 - INFO - onboarding.py:207 - Quiz sent, waiting for response...
2023-12-21 14:36:24,801 - INFO - main.py:7 - Bot started!
2023-12-21 14:37:12,487 - INFO - onboarding.py:204 - Sending quiz: What is the capital of France?
2023-12-21 14:37:12,730 - INFO - onboarding.py:207 - Quiz sent, waiting for response...
2023-12-21 14:37:12,730 - INFO - onboarding.py:212 - Entered handle_quiz_answer
2023-12-21 14:37:12,730 - WARNING - main.py:10 - Update "{'callback_query': {'id': '6961276461707031452', 'chat_instance': '-3241866149608258687', 'message': {'supergroup_chat_created': False, 'photo': [], 'message_id': 968, 'reply_markup': {'inline_keyboard': [[{'text': "I've watched the video, proceed to the quiz", 'callback_data': 'proceed_to_quiz'}]]}, 'group_chat_created': False, 'date': 1703169430, 'chat': {'first_name': 'Talisha', 'id': 5915765775, 'last_name': 'White', 'username': 'realtalishaw', 'type': 'private'}, 'channel_chat_created': False, 'new_chat_photo': [], 'delete_chat_photo': False, 'new_chat_members': [], 'text': "Click the button when you're ready to proceed to the quiz.", 'entities': [], 'caption_entities': [], 'from': {'id': 6887127186, 'first_name': 'TheoBot', 'is_bot': True, 'username': 'theometricsbot'}}, 'data': 'proceed_to_quiz', 'from': {'id': 5915765775, 'last_name': 'White', 'language_code': 'en', 'first_name': 'Talisha', 'is_bot': False, 'username': 'realtalishaw'}}, 'update_id': 978926146}" caused error "'NoneType' object has no attribute 'option_ids'"
2023-12-21 14:40:39,242 - INFO - main.py:7 - Bot started!
2023-12-21 14:41:32,747 - INFO - onboarding.py:204 - Sending quiz: What is the capital of France?
2023-12-21 14:41:32,973 - INFO - onboarding.py:207 - Quiz sent, waiting for response...
2023-12-21 14:42:13,083 - INFO - main.py:7 - Bot started!
2023-12-21 14:42:58,586 - INFO - onboarding.py:204 - Sending quiz: What is the capital of France?
2023-12-21 14:42:58,820 - INFO - onboarding.py:207 - Quiz sent, waiting for response...
2023-12-21 15:08:18,658 - INFO - main.py:7 - Bot started!
2023-12-21 15:09:04,891 - INFO - onboarding.py:204 - Sending quiz: What is the capital of France?
2023-12-21 15:09:05,137 - INFO - onboarding.py:207 - +++++++++++++++++++Quiz sent, waiting for response...
2023-12-21 15:25:31,950 - INFO - main.py:7 - Bot started!
2023-12-21 15:27:47,817 - INFO - main.py:7 - Bot started!
2023-12-21 15:33:29,713 - INFO - main.py:7 - Bot started!
2023-12-21 15:37:58,595 - INFO - main.py:7 - Bot started!
2023-12-21 17:10:10,706 - INFO - main.py:7 - Bot started!
2023-12-21 17:12:27,026 - INFO - main.py:7 - Bot started!
2023-12-22 12:39:29,768 - INFO - main.py:7 - Bot started!
2023-12-22 12:41:07,094 - INFO - main.py:7 - Bot started!
2023-12-22 12:41:58,813 - WARNING - main.py:10 - Update "{'callback_query': {'message': {'text': 'Incorrect, please try again.\n\nWhat is the capital of France?', 'new_chat_members': [], 'group_chat_created': False, 'entities': [], 'reply_markup': {'inline_keyboard': [[{'text': 'London', 'callback_data': 'London'}], [{'text': 'Paris', 'callback_data': 'Paris'}], [{'text': 'Berlin', 'callback_data': 'Berlin'}], [{'text': 'Rome', 'callback_data': 'Rome'}]]}, 'message_id': 1143, 'chat': {'last_name': 'White', 'type': 'private', 'username': 'realtalishaw', 'id': 5915765775, 'first_name': 'Talisha'}, 'caption_entities': [], 'new_chat_photo': [], 'supergroup_chat_created': False, 'delete_chat_photo': False, 'photo': [], 'edit_date': 1703248916, 'channel_chat_created': False, 'date': 1703248915, 'from': {'username': 'theometricsbot', 'is_bot': True, 'id': 6887127186, 'first_name': 'TheoBot'}}, 'data': 'Paris', 'id': '6961276463608237819', 'chat_instance': '-3241866149608258687', 'from': {'last_name': 'White', 'language_code': 'en', 'username': 'realtalishaw', 'is_bot': False, 'id': 5915765775, 'first_name': 'Talisha'}}, 'update_id': 978926250}" caused error "Message is not modified: specified new message content and reply markup are exactly the same as a current content and reply markup of the message"
2023-12-22 12:43:31,507 - INFO - main.py:7 - Bot started!
2023-12-22 12:44:26,316 - WARNING - main.py:10 - Update "{'update_id': 978926258, 'callback_query': {'id': '6961276463392610840', 'data': 'yes', 'message': {'supergroup_chat_created': False, 'chat': {'id': 5915765775, 'type': 'private', 'username': 'realtalishaw', 'first_name': 'Talisha', 'last_name': 'White'}, 'caption_entities': [], 'message_id': 1159, 'entities': [], 'channel_chat_created': False, 'photo': [], 'delete_chat_photo': False, 'group_chat_created': False, 'new_chat_members': [], 'text': 'Is this information correct?', 'date': 1703249064, 'new_chat_photo': [], 'reply_markup': {'inline_keyboard': [[{'callback_data': 'yes', 'text': 'Yes'}, {'callback_data': 'no', 'text': 'No'}]]}, 'from': {'id': 6887127186, 'first_name': 'TheoBot', 'username': 'theometricsbot', 'is_bot': True}}, 'chat_instance': '-3241866149608258687', 'from': {'id': 5915765775, 'first_name': 'Talisha', 'language_code': 'en', 'username': 'realtalishaw', 'last_name': 'White', 'is_bot': False}}}" caused error "name 'watch_vido' is not defined"
2023-12-22 12:45:12,676 - INFO - main.py:7 - Bot started!
2023-12-22 12:50:15,987 - INFO - main.py:7 - Bot started!
2023-12-22 13:17:09,174 - INFO - main.py:7 - Bot started!
2023-12-22 15:12:25,451 - INFO - main.py:8 - Bot started!
2023-12-22 15:13:21,200 - INFO - main.py:8 - Bot started!
2023-12-22 15:15:58,806 - INFO - main.py:8 - Bot started!
2023-12-22 15:16:44,405 - WARNING - main.py:11 - Update "{'callback_query': {'message': {'date': 1703258203, 'entities': [], 'channel_chat_created': False, 'delete_chat_photo': False, 'caption_entities': [], 'text': 'In which year did the Titanic sink?', 'new_chat_photo': [], 'new_chat_members': [], 'message_id': 1315, 'reply_markup': {'inline_keyboard': [[{'callback_data': 'True', 'text': '1912'}, {'callback_data': 'False', 'text': '1910'}, {'callback_data': 'False', 'text': '1914'}, {'callback_data': 'False', 'text': '1908'}]]}, 'photo': [], 'group_chat_created': False, 'chat': {'id': 5915765775, 'first_name': 'Talisha', 'username': 'realtalishaw', 'type': 'private', 'last_name': 'White'}, 'supergroup_chat_created': False, 'from': {'username': 'theometricsbot', 'id': 6887127186, 'is_bot': True, 'first_name': 'TheoBot'}}, 'chat_instance': '-3241866149608258687', 'data': 'True', 'id': '6961276463006195305', 'from': {'username': 'realtalishaw', 'last_name': 'White', 'language_code': 'en', 'id': 5915765775, 'is_bot': False, 'first_name': 'Talisha'}}, 'update_id': 978926351}" caused error "'NoneType' object has no attribute 'reply_text'"
2023-12-22 15:18:48,935 - WARNING - main.py:11 - Update "{'callback_query': {'message': {'date': 1703258203, 'entities': [], 'channel_chat_created': False, 'delete_chat_photo': False, 'caption_entities': [], 'text': 'In which year did the Titanic sink?', 'new_chat_photo': [], 'new_chat_members': [], 'message_id': 1315, 'reply_markup': {'inline_keyboard': [[{'callback_data': 'True', 'text': '1912'}, {'callback_data': 'False', 'text': '1910'}, {'callback_data': 'False', 'text': '1914'}, {'callback_data': 'False', 'text': '1908'}]]}, 'photo': [], 'group_chat_created': False, 'chat': {'id': 5915765775, 'first_name': 'Talisha', 'username': 'realtalishaw', 'type': 'private', 'last_name': 'White'}, 'supergroup_chat_created': False, 'from': {'username': 'theometricsbot', 'id': 6887127186, 'is_bot': True, 'first_name': 'TheoBot'}}, 'chat_instance': '-3241866149608258687', 'data': 'False', 'id': '6961276464472973924', 'from': {'username': 'realtalishaw', 'last_name': 'White', 'language_code': 'en', 'id': 5915765775, 'is_bot': False, 'first_name': 'Talisha'}}, 'update_id': 978926352}" caused error "list index out of range"
2023-12-22 15:18:51,373 - WARNING - main.py:11 - Update "{'callback_query': {'message': {'date': 1703258203, 'entities': [], 'channel_chat_created': False, 'delete_chat_photo': False, 'caption_entities': [], 'text': 'In which year did the Titanic sink?', 'new_chat_photo': [], 'new_chat_members': [], 'message_id': 1315, 'reply_markup': {'inline_keyboard': [[{'callback_data': 'True', 'text': '1912'}, {'callback_data': 'False', 'text': '1910'}, {'callback_data': 'False', 'text': '1914'}, {'callback_data': 'False', 'text': '1908'}]]}, 'photo': [], 'group_chat_created': False, 'chat': {'id': 5915765775, 'first_name': 'Talisha', 'username': 'realtalishaw', 'type': 'private', 'last_name': 'White'}, 'supergroup_chat_created': False, 'from': {'username': 'theometricsbot', 'id': 6887127186, 'is_bot': True, 'first_name': 'TheoBot'}}, 'chat_instance': '-3241866149608258687', 'data': 'False', 'id': '6961276461734844105', 'from': {'username': 'realtalishaw', 'last_name': 'White', 'language_code': 'en', 'id': 5915765775, 'is_bot': False, 'first_name': 'Talisha'}}, 'update_id': 978926353}" caused error "list index out of range"
2023-12-22 15:18:53,061 - WARNING - main.py:11 - Update "{'callback_query': {'message': {'date': 1703258203, 'entities': [], 'channel_chat_created': False, 'delete_chat_photo': False, 'caption_entities': [], 'text': 'In which year did the Titanic sink?', 'new_chat_photo': [], 'new_chat_members': [], 'message_id': 1315, 'reply_markup': {'inline_keyboard': [[{'callback_data': 'True', 'text': '1912'}, {'callback_data': 'False', 'text': '1910'}, {'callback_data': 'False', 'text': '1914'}, {'callback_data': 'False', 'text': '1908'}]]}, 'photo': [], 'group_chat_created': False, 'chat': {'id': 5915765775, 'first_name': 'Talisha', 'username': 'realtalishaw', 'type': 'private', 'last_name': 'White'}, 'supergroup_chat_created': False, 'from': {'username': 'theometricsbot', 'id': 6887127186, 'is_bot': True, 'first_name': 'TheoBot'}}, 'chat_instance': '-3241866149608258687', 'data': 'False', 'id': '6961276464894071524', 'from': {'username': 'realtalishaw', 'last_name': 'White', 'language_code': 'en', 'id': 5915765775, 'is_bot': False, 'first_name': 'Talisha'}}, 'update_id': 978926354}" caused error "list index out of range"
2023-12-22 15:18:54,483 - WARNING - main.py:11 - Update "{'callback_query': {'message': {'date': 1703258203, 'entities': [], 'channel_chat_created': False, 'delete_chat_photo': False, 'caption_entities': [], 'text': 'In which year did the Titanic sink?', 'new_chat_photo': [], 'new_chat_members': [], 'message_id': 1315, 'reply_markup': {'inline_keyboard': [[{'callback_data': 'True', 'text': '1912'}, {'callback_data': 'False', 'text': '1910'}, {'callback_data': 'False', 'text': '1914'}, {'callback_data': 'False', 'text': '1908'}]]}, 'photo': [], 'group_chat_created': False, 'chat': {'id': 5915765775, 'first_name': 'Talisha', 'username': 'realtalishaw', 'type': 'private', 'last_name': 'White'}, 'supergroup_chat_created': False, 'from': {'username': 'theometricsbot', 'id': 6887127186, 'is_bot': True, 'first_name': 'TheoBot'}}, 'chat_instance': '-3241866149608258687', 'data': 'True', 'id': '6961276464565900982', 'from': {'username': 'realtalishaw', 'last_name': 'White', 'language_code': 'en', 'id': 5915765775, 'is_bot': False, 'first_name': 'Talisha'}}, 'update_id': 978926355}" caused error "'NoneType' object has no attribute 'reply_text'"
2023-12-22 15:25:17,485 - INFO - main.py:8 - Bot started!
2023-12-22 15:26:22,792 - INFO - user.py:15 - API Request, create_user
2023-12-22 15:26:25,069 - INFO - api_call.py:29 - API POST request for users failed with error 400 Client Error: Bad Request for url: https://dqpllfj7tb.execute-api.us-east-1.amazonaws.com/dev/users
2023-12-22 15:26:25,071 - ERROR - onboarding.py:270 - Error in onboarding_complete: 'NoneType' object has no attribute 'status_code'
2023-12-22 15:26:25,072 - WARNING - main.py:11 - Update "{'callback_query': {'data': 'True', 'chat_instance': '-3241866149608258687', 'id': '6961276464982921929', 'message': {'caption_entities': [], 'photo': [], 'entities': [], 'date': 1703258781, 'chat': {'type': 'private', 'id': 5915765775, 'username': 'realtalishaw', 'first_name': 'Talisha', 'last_name': 'White'}, 'message_id': 1349, 'channel_chat_created': False, 'group_chat_created': False, 'text': 'In which year did the Titanic sink?', 'new_chat_photo': [], 'supergroup_chat_created': False, 'new_chat_members': [], 'reply_markup': {'inline_keyboard': [[{'callback_data': 'True', 'text': '1912'}, {'callback_data': 'False', 'text': '1910'}, {'callback_data': 'False', 'text': '1914'}, {'callback_data': 'False', 'text': '1908'}]]}, 'delete_chat_photo': False, 'from': {'is_bot': True, 'id': 6887127186, 'username': 'theometricsbot', 'first_name': 'TheoBot'}}, 'from': {'is_bot': False, 'id': 5915765775, 'language_code': 'en', 'username': 'realtalishaw', 'first_name': 'Talisha', 'last_name': 'White'}}, 'update_id': 978926373}" caused error "'NoneType' object has no attribute 'reply_text'"
2023-12-22 15:47:12,715 - WARNING - main.py:11 - Update "None" caused error "urllib3 HTTPError [SSL: UNEXPECTED_EOF_WHILE_READING] EOF occurred in violation of protocol (_ssl.c:1007)"
2023-12-22 16:01:13,524 - INFO - main.py:8 - Bot started!
2023-12-22 16:02:16,069 - INFO - user.py:15 - API Request, create_user
2023-12-22 16:02:18,441 - INFO - api_call.py:29 - API POST request for users failed with error 400 Client Error: Bad Request for url: https://dqpllfj7tb.execute-api.us-east-1.amazonaws.com/dev/users
2023-12-22 16:02:18,443 - ERROR - onboarding.py:270 - Error in onboarding_complete: 'NoneType' object has no attribute 'status_code'
2023-12-22 16:02:18,444 - WARNING - main.py:11 - Update "{'callback_query': {'id': '6961276462837715658', 'data': 'True', 'message': {'date': 1703260934, 'photo': [], 'chat': {'username': 'realtalishaw', 'type': 'private', 'last_name': 'White', 'first_name': 'Talisha', 'id': 5915765775}, 'new_chat_members': [], 'caption_entities': [], 'supergroup_chat_created': False, 'new_chat_photo': [], 'message_id': 1381, 'group_chat_created': False, 'entities': [], 'delete_chat_photo': False, 'text': 'In which year did the Titanic sink?', 'channel_chat_created': False, 'reply_markup': {'inline_keyboard': [[{'text': '1912', 'callback_data': 'True'}, {'text': '1910', 'callback_data': 'False'}, {'text': '1914', 'callback_data': 'False'}, {'text': '1908', 'callback_data': 'False'}]]}, 'from': {'id': 6887127186, 'username': 'theometricsbot', 'is_bot': True, 'first_name': 'TheoBot'}}, 'chat_instance': '-3241866149608258687', 'from': {'id': 5915765775, 'last_name': 'White', 'username': 'realtalishaw', 'is_bot': False, 'language_code': 'en', 'first_name': 'Talisha'}}, 'update_id': 978926391}" caused error "'NoneType' object has no attribute 'reply_text'"
2023-12-22 16:21:42,292 - INFO - main.py:8 - Bot started!
2023-12-22 16:22:45,257 - INFO - user.py:15 - API Request, create_user
2023-12-22 16:22:47,560 - ERROR - onboarding.py:270 - Error in onboarding_complete: 'NoneType' object has no attribute 'reply_text'
2023-12-22 16:22:47,561 - WARNING - main.py:11 - Update "{'callback_query': {'message': {'new_chat_members': [], 'supergroup_chat_created': False, 'message_id': 1417, 'entities': [], 'channel_chat_created': False, 'photo': [], 'reply_markup': {'inline_keyboard': [[{'callback_data': 'True', 'text': '1912'}, {'callback_data': 'False', 'text': '1910'}, {'callback_data': 'False', 'text': '1914'}, {'callback_data': 'False', 'text': '1908'}]]}, 'delete_chat_photo': False, 'chat': {'type': 'private', 'last_name': 'White', 'first_name': 'Talisha', 'username': 'realtalishaw', 'id': 5915765775}, 'text': 'In which year did the Titanic sink?', 'group_chat_created': False, 'caption_entities': [], 'date': 1703262163, 'new_chat_photo': [], 'from': {'username': 'theometricsbot', 'first_name': 'TheoBot', 'is_bot': True, 'id': 6887127186}}, 'chat_instance': '-3241866149608258687', 'data': 'True', 'id': '6961276464260004271', 'from': {'last_name': 'White', 'username': 'realtalishaw', 'first_name': 'Talisha', 'is_bot': False, 'language_code': 'en', 'id': 5915765775}}, 'update_id': 978926411}" caused error "'NoneType' object has no attribute 'reply_text'"
2023-12-22 16:27:29,509 - INFO - main.py:8 - Bot started!
2023-12-22 16:28:21,500 - INFO - user.py:15 - API Request, create_user
2023-12-22 16:28:24,154 - ERROR - onboarding.py:274 - Error in onboarding_complete: Chat not found
2023-12-22 16:31:21,259 - INFO - main.py:8 - Bot started!
2023-12-22 16:32:27,991 - INFO - user.py:15 - API Request, create_user
2023-12-22 16:32:30,288 - INFO - api_call.py:29 - API POST request for users failed with error 400 Client Error: Bad Request for url: https://dqpllfj7tb.execute-api.us-east-1.amazonaws.com/dev/users
2023-12-22 16:32:30,290 - ERROR - onboarding.py:270 - API Request failed: No response from API
2023-12-22 16:33:49,611 - INFO - user.py:15 - API Request, create_user
2023-12-22 16:33:54,582 - WARNING - main.py:11 - Update "{'callback_query': {'id': '6961276460795991561', 'chat_instance': '-3241866149608258687', 'message': {'date': 1703262830, 'chat': {'last_name': 'White', 'username': 'realtalishaw', 'first_name': 'Talisha', 'id': 5915765775, 'type': 'private'}, 'supergroup_chat_created': False, 'delete_chat_photo': False, 'message_id': 1527, 'reply_markup': {'inline_keyboard': [[{'callback_data': 'approve_5915765775', 'text': 'Approve'}], [{'callback_data': 'deny_5915765775', 'text': 'Deny'}]]}, 'caption_entities': [], 'photo': [], 'text': 'New user registration:\nid: 5915765775\nfirstName: Talisha\nlastName: White\nemail: a@a.com\nphone: 0123654789\nusername: realtalishaw\ncompletedOnboarding: True\nrole: MEMBER\nbio: f\nstatus: PENDING', 'group_chat_created': False, 'new_chat_members': [], 'new_chat_photo': [], 'entities': [{'offset': 80, 'type': 'email', 'length': 7}], 'channel_chat_created': False, 'from': {'username': 'theometricsbot', 'is_bot': True, 'first_name': 'TheoBot', 'id': 6887127186}}, 'data': 'approve_5915765775', 'from': {'username': 'realtalishaw', 'language_code': 'en', 'is_bot': False, 'first_name': 'Talisha', 'last_name': 'White', 'id': 5915765775}}, 'update_id': 978926470}" caused error "list index out of range"
2023-12-22 16:33:58,822 - WARNING - main.py:11 - Update "{'callback_query': {'id': '6961276461445373371', 'chat_instance': '-3241866149608258687', 'message': {'date': 1703262830, 'chat': {'last_name': 'White', 'username': 'realtalishaw', 'first_name': 'Talisha', 'id': 5915765775, 'type': 'private'}, 'supergroup_chat_created': False, 'delete_chat_photo': False, 'message_id': 1527, 'reply_markup': {'inline_keyboard': [[{'callback_data': 'approve_5915765775', 'text': 'Approve'}], [{'callback_data': 'deny_5915765775', 'text': 'Deny'}]]}, 'caption_entities': [], 'photo': [], 'text': 'New user registration:\nid: 5915765775\nfirstName: Talisha\nlastName: White\nemail: a@a.com\nphone: 0123654789\nusername: realtalishaw\ncompletedOnboarding: True\nrole: MEMBER\nbio: f\nstatus: PENDING', 'group_chat_created': False, 'new_chat_members': [], 'new_chat_photo': [], 'entities': [{'offset': 80, 'type': 'email', 'length': 7}], 'channel_chat_created': False, 'from': {'username': 'theometricsbot', 'is_bot': True, 'first_name': 'TheoBot', 'id': 6887127186}}, 'data': 'approve_5915765775', 'from': {'username': 'realtalishaw', 'language_code': 'en', 'is_bot': False, 'first_name': 'Talisha', 'last_name': 'White', 'id': 5915765775}}, 'update_id': 978926471}" caused error "list index out of range"
2023-12-22 16:34:02,663 - WARNING - main.py:11 - Update "{'callback_query': {'id': '6961276460828515694', 'chat_instance': '-3241866149608258687', 'message': {'date': 1703262830, 'chat': {'last_name': 'White', 'username': 'realtalishaw', 'first_name': 'Talisha', 'id': 5915765775, 'type': 'private'}, 'supergroup_chat_created': False, 'delete_chat_photo': False, 'message_id': 1527, 'reply_markup': {'inline_keyboard': [[{'callback_data': 'approve_5915765775', 'text': 'Approve'}], [{'callback_data': 'deny_5915765775', 'text': 'Deny'}]]}, 'caption_entities': [], 'photo': [], 'text': 'New user registration:\nid: 5915765775\nfirstName: Talisha\nlastName: White\nemail: a@a.com\nphone: 0123654789\nusername: realtalishaw\ncompletedOnboarding: True\nrole: MEMBER\nbio: f\nstatus: PENDING', 'group_chat_created': False, 'new_chat_members': [], 'new_chat_photo': [], 'entities': [{'offset': 80, 'type': 'email', 'length': 7}], 'channel_chat_created': False, 'from': {'username': 'theometricsbot', 'is_bot': True, 'first_name': 'TheoBot', 'id': 6887127186}}, 'data': 'deny_5915765775', 'from': {'username': 'realtalishaw', 'language_code': 'en', 'is_bot': False, 'first_name': 'Talisha', 'last_name': 'White', 'id': 5915765775}}, 'update_id': 978926472}" caused error "list index out of range"
2023-12-22 16:36:01,012 - INFO - main.py:8 - Bot started!
2023-12-22 16:36:54,490 - INFO - user.py:15 - API Request, create_user
2023-12-22 16:36:55,187 - INFO - api_call.py:29 - API POST request for users failed with error 400 Client Error: Bad Request for url: https://dqpllfj7tb.execute-api.us-east-1.amazonaws.com/dev/users
2023-12-22 16:36:55,188 - ERROR - onboarding.py:271 - API Request failed: No response from API
2023-12-22 16:38:18,281 - INFO - user.py:15 - API Request, create_user
2023-12-24 16:34:47,635 - INFO - main.py:8 - Bot started!
2023-12-24 16:34:52,739 - WARNING - main.py:11 - Update "None" caused error "Conflict: terminated by other getUpdates request; make sure that only one bot instance is running"
2023-12-24 16:34:58,545 - WARNING - main.py:11 - Update "None" caused error "Conflict: terminated by other getUpdates request; make sure that only one bot instance is running"
2023-12-24 16:45:56,925 - INFO - main.py:8 - Bot started!
2023-12-24 16:53:44,922 - INFO - main.py:8 - Bot started!
2023-12-24 17:06:43,092 - INFO - main.py:8 - Bot started!
2023-12-24 17:10:06,436 - INFO - main.py:8 - Bot started!
2023-12-24 17:10:55,333 - INFO - main.py:8 - Bot started!
2023-12-24 17:13:48,533 - INFO - main.py:8 - Bot started!
2023-12-24 17:14:34,936 - INFO - task.py:13 - API Request, create_task
2023-12-24 17:14:36,459 - INFO - api_call.py:29 - API POST request for tasks failed with error 400 Client Error: Bad Request for url: https://dqpllfj7tb.execute-api.us-east-1.amazonaws.com/dev/tasks
2023-12-24 17:17:57,168 - INFO - main.py:8 - Bot started!
2023-12-24 17:18:52,713 - INFO - main.py:8 - Bot started!
2023-12-24 17:19:04,826 - INFO - task.py:13 - API Request, create_task
2023-12-24 17:19:05,509 - INFO - api_call.py:29 - API POST request for tasks failed with error 400 Client Error: Bad Request for url: https://dqpllfj7tb.execute-api.us-east-1.amazonaws.com/dev/tasks
2023-12-24 18:07:11,364 - WARNING - main.py:11 - Update "None" caused error "urllib3 HTTPError HTTPSConnectionPool(host='api.telegram.org', port=443): Max retries exceeded with url: /bot6527896537:AAHHAekqlPv3AHsD9-gkYSAfWc8NW1Vk2Yw/getUpdates (Caused by NewConnectionError('<telegram.vendor.ptb_urllib3.urllib3.connection.VerifiedHTTPSConnection object at 0x104beed50>: Failed to establish a new connection: [Errno 8] nodename nor servname provided, or not known'))"
2023-12-24 18:07:12,377 - WARNING - main.py:11 - Update "None" caused error "urllib3 HTTPError HTTPSConnectionPool(host='api.telegram.org', port=443): Max retries exceeded with url: /bot6527896537:AAHHAekqlPv3AHsD9-gkYSAfWc8NW1Vk2Yw/getUpdates (Caused by NewConnectionError('<telegram.vendor.ptb_urllib3.urllib3.connection.VerifiedHTTPSConnection object at 0x104bef550>: Failed to establish a new connection: [Errno 8] nodename nor servname provided, or not known'))"
2023-12-24 18:15:13,641 - INFO - main.py:10 - Bot started!
2023-12-27 17:10:47,175 - INFO - main.py:10 - Bot started!
2023-12-27 17:11:03,377 - INFO - task.py:13 - API Request, create_task
2023-12-27 17:11:04,763 - INFO - api_call.py:29 - API POST request for tasks failed with error 400 Client Error: Bad Request for url: https://dqpllfj7tb.execute-api.us-east-1.amazonaws.com/dev/tasks
2023-12-27 17:11:48,391 - INFO - task.py:13 - API Request, create_task
2023-12-27 17:11:48,908 - INFO - api_call.py:29 - API POST request for tasks failed with error 400 Client Error: Bad Request for url: https://dqpllfj7tb.execute-api.us-east-1.amazonaws.com/dev/tasks
2023-12-27 17:16:18,679 - INFO - main.py:10 - Bot started!
2023-12-27 17:16:37,662 - INFO - task.py:13 - API Request, create_task
2023-12-27 17:19:03,001 - INFO - main.py:10 - Bot started!
2023-12-27 17:19:15,184 - INFO - task.py:13 - API Request, create_task
2023-12-27 17:19:15,876 - INFO - api_call.py:29 - API POST request for tasks failed with error 500 Server Error: Internal Server Error for url: https://dqpllfj7tb.execute-api.us-east-1.amazonaws.com/dev/tasks
2023-12-27 17:19:47,154 - INFO - main.py:10 - Bot started!
2023-12-27 17:19:56,599 - INFO - task.py:13 - API Request, create_task
2023-12-27 17:19:57,178 - INFO - api_call.py:29 - API POST request for tasks failed with error 500 Server Error: Internal Server Error for url: https://dqpllfj7tb.execute-api.us-east-1.amazonaws.com/dev/tasks
2023-12-27 17:20:50,450 - INFO - main.py:10 - Bot started!
2023-12-27 17:20:57,989 - WARNING - main.py:13 - Update "{'message': {'photo': [], 'chat': {'last_name': 'help', 'id': 503241607, 'first_name': 'future', 'type': 'private', 'username': 'imfuturehelp'}, 'date': 1703715657, 'new_chat_members': [], 'supergroup_chat_created': False, 'delete_chat_photo': False, 'new_chat_photo': [], 'group_chat_created': False, 'message_id': 130, 'caption_entities': [], 'channel_chat_created': False, 'text': '/createtask drew test 10012 testing testing testing', 'entities': [{'type': 'bot_command', 'offset': 0, 'length': 11}], 'from': {'first_name': 'future', 'last_name': 'help', 'language_code': 'en', 'is_bot': False, 'id': 503241607, 'username': 'imfuturehelp'}}, 'update_id': 556864819}" caused error "list index out of range"
2023-12-27 17:21:41,149 - INFO - main.py:10 - Bot started!
2023-12-27 17:21:45,713 - INFO - task.py:13 - API Request, create_task
2023-12-27 17:21:46,296 - INFO - api_call.py:29 - API POST request for tasks failed with error 500 Server Error: Internal Server Error for url: https://dqpllfj7tb.execute-api.us-east-1.amazonaws.com/dev/tasks
2023-12-27 17:24:07,939 - INFO - main.py:10 - Bot started!
2023-12-27 17:24:17,139 - INFO - task.py:13 - API Request, create_task
2023-12-27 17:24:17,859 - INFO - api_call.py:29 - API POST request for tasks failed with error 500 Server Error: Internal Server Error for url: https://dqpllfj7tb.execute-api.us-east-1.amazonaws.com/dev/tasks
2023-12-27 17:25:39,703 - INFO - main.py:10 - Bot started!
2023-12-27 17:25:45,435 - INFO - task.py:13 - API Request, create_task
2023-12-27 17:25:46,199 - INFO - api_call.py:29 - API POST request for tasks failed with error 500 Server Error: Internal Server Error for url: https://dqpllfj7tb.execute-api.us-east-1.amazonaws.com/dev/tasks
2023-12-27 17:27:18,080 - INFO - main.py:10 - Bot started!
2023-12-27 17:27:24,330 - INFO - task.py:13 - API Request, create_task
2023-12-27 17:27:24,891 - INFO - api_call.py:29 - API POST request for tasks failed with error 500 Server Error: Internal Server Error for url: https://dqpllfj7tb.execute-api.us-east-1.amazonaws.com/dev/tasks
2023-12-27 17:28:06,497 - INFO - main.py:10 - Bot started!
2023-12-27 17:28:12,919 - INFO - task.py:13 - API Request, create_task
2023-12-27 17:28:13,452 - INFO - api_call.py:29 - API POST request for tasks failed with error 500 Server Error: Internal Server Error for url: https://dqpllfj7tb.execute-api.us-east-1.amazonaws.com/dev/tasks
2023-12-27 17:28:55,650 - INFO - main.py:10 - Bot started!
2023-12-27 17:29:00,568 - INFO - task.py:13 - API Request, create_task
2023-12-27 17:29:01,214 - INFO - api_call.py:29 - API POST request for tasks failed with error 500 Server Error: Internal Server Error for url: https://dqpllfj7tb.execute-api.us-east-1.amazonaws.com/dev/tasks
2023-12-27 17:29:36,878 - INFO - task.py:13 - API Request, create_task
2023-12-27 17:29:37,395 - INFO - api_call.py:29 - API POST request for tasks failed with error 500 Server Error: Internal Server Error for url: https://dqpllfj7tb.execute-api.us-east-1.amazonaws.com/dev/tasks
2023-12-27 17:30:19,221 - INFO - main.py:10 - Bot started!
2023-12-27 17:30:24,167 - INFO - task.py:13 - API Request, create_task
2023-12-27 17:30:32,506 - INFO - task.py:13 - API Request, create_task
2023-12-27 17:32:51,774 - INFO - main.py:10 - Bot started!
2023-12-27 17:32:57,531 - INFO - task.py:13 - API Request, create_task
2023-12-27 17:35:00,878 - INFO - main.py:10 - Bot started!
2023-12-27 17:35:14,831 - WARNING - main.py:13 - Update "{'message': {'group_chat_created': False, 'caption_entities': [], 'date': 1703716514, 'text': '/createtask drew test 10012 testing testing testing', 'chat': {'first_name': 'future', 'type': 'private', 'id': 503241607, 'username': 'imfuturehelp', 'last_name': 'help'}, 'new_chat_photo': [], 'delete_chat_photo': False, 'message_id': 151, 'photo': [], 'channel_chat_created': False, 'supergroup_chat_created': False, 'new_chat_members': [], 'entities': [{'offset': 0, 'length': 11, 'type': 'bot_command'}], 'from': {'last_name': 'help', 'language_code': 'en', 'is_bot': False, 'first_name': 'future', 'id': 503241607, 'username': 'imfuturehelp'}}, 'update_id': 556864830}" caused error "list index out of range"
2023-12-27 17:36:27,241 - INFO - main.py:10 - Bot started!
2023-12-27 17:36:38,853 - WARNING - main.py:13 - Update "{'update_id': 556864831, 'message': {'date': 1703716598, 'delete_chat_photo': False, 'channel_chat_created': False, 'supergroup_chat_created': False, 'chat': {'type': 'private', 'first_name': 'future', 'username': 'imfuturehelp', 'id': 503241607, 'last_name': 'help'}, 'entities': [{'type': 'bot_command', 'length': 11, 'offset': 0}], 'new_chat_members': [], 'group_chat_created': False, 'photo': [], 'message_id': 152, 'caption_entities': [], 'new_chat_photo': [], 'text': '/createtask drew test 10012 testing testing testing', 'from': {'is_bot': False, 'last_name': 'help', 'first_name': 'future', 'language_code': 'en', 'username': 'imfuturehelp', 'id': 503241607}}}" caused error "list index out of range"
2023-12-27 17:40:44,253 - INFO - main.py:10 - Bot started!
2023-12-27 17:40:50,257 - WARNING - main.py:13 - Update "{'update_id': 556864832, 'message': {'supergroup_chat_created': False, 'delete_chat_photo': False, 'entities': [{'type': 'bot_command', 'offset': 0, 'length': 11}], 'group_chat_created': False, 'caption_entities': [], 'channel_chat_created': False, 'date': 1703716850, 'text': '/createtask drew test 10012 testing testing testing', 'new_chat_photo': [], 'message_id': 153, 'new_chat_members': [], 'photo': [], 'chat': {'type': 'private', 'first_name': 'future', 'last_name': 'help', 'id': 503241607, 'username': 'imfuturehelp'}, 'from': {'username': 'imfuturehelp', 'language_code': 'en', 'last_name': 'help', 'first_name': 'future', 'id': 503241607, 'is_bot': False}}}" caused error "list index out of range"
2023-12-27 17:41:56,441 - INFO - main.py:10 - Bot started!
2023-12-27 17:42:01,540 - WARNING - main.py:13 - Update "{'update_id': 556864833, 'message': {'entities': [{'length': 11, 'offset': 0, 'type': 'bot_command'}], 'date': 1703716921, 'message_id': 154, 'group_chat_created': False, 'new_chat_members': [], 'photo': [], 'text': '/createtask drew test 10012 testing testing testing', 'channel_chat_created': False, 'delete_chat_photo': False, 'supergroup_chat_created': False, 'caption_entities': [], 'chat': {'id': 503241607, 'username': 'imfuturehelp', 'first_name': 'future', 'last_name': 'help', 'type': 'private'}, 'new_chat_photo': [], 'from': {'username': 'imfuturehelp', 'id': 503241607, 'language_code': 'en', 'is_bot': False, 'first_name': 'future', 'last_name': 'help'}}}" caused error "cannot access local variable 'payload' where it is not associated with a value"
2023-12-27 17:42:33,605 - INFO - main.py:10 - Bot started!
2023-12-27 17:42:39,256 - WARNING - main.py:13 - Update "{'message': {'photo': [], 'chat': {'last_name': 'help', 'type': 'private', 'first_name': 'future', 'username': 'imfuturehelp', 'id': 503241607}, 'group_chat_created': False, 'new_chat_members': [], 'text': '/createtask drew test 10012 testing testing testing', 'caption_entities': [], 'new_chat_photo': [], 'channel_chat_created': False, 'date': 1703716959, 'supergroup_chat_created': False, 'message_id': 155, 'entities': [{'type': 'bot_command', 'length': 11, 'offset': 0}], 'delete_chat_photo': False, 'from': {'is_bot': False, 'last_name': 'help', 'first_name': 'future', 'username': 'imfuturehelp', 'language_code': 'en', 'id': 503241607}}, 'update_id': 556864834}" caused error "list index out of range"
2023-12-27 17:43:29,784 - INFO - main.py:10 - Bot started!
2023-12-27 17:43:37,061 - INFO - task.py:13 - API Request, create_task
2023-12-27 17:43:39,626 - INFO - api_call.py:29 - API POST request for tasks failed with error 500 Server Error: Internal Server Error for url: https://dqpllfj7tb.execute-api.us-east-1.amazonaws.com/dev/tasks
2023-12-27 17:45:04,236 - INFO - main.py:10 - Bot started!
2023-12-27 17:45:09,767 - INFO - task.py:13 - API Request, create_task
2023-12-27 17:45:11,005 - INFO - api_call.py:29 - API POST request for tasks failed with error 500 Server Error: Internal Server Error for url: https://dqpllfj7tb.execute-api.us-east-1.amazonaws.com/dev/tasks
2023-12-27 17:46:16,766 - INFO - main.py:10 - Bot started!
2023-12-27 17:46:24,465 - WARNING - main.py:13 - Update "{'message': {'new_chat_photo': [], 'supergroup_chat_created': False, 'chat': {'last_name': 'help', 'first_name': 'future', 'username': 'imfuturehelp', 'type': 'private', 'id': 503241607}, 'group_chat_created': False, 'date': 1703717184, 'caption_entities': [], 'entities': [{'length': 11, 'offset': 0, 'type': 'bot_command'}], 'photo': [], 'message_id': 162, 'delete_chat_photo': False, 'channel_chat_created': False, 'new_chat_members': [], 'text': '/createtask drew test 10012 testing testing testing', 'from': {'language_code': 'en', 'id': 503241607, 'first_name': 'future', 'username': 'imfuturehelp', 'is_bot': False, 'last_name': 'help'}}, 'update_id': 556864837}" caused error "list index out of range"
2023-12-27 17:46:49,043 - WARNING - main.py:13 - Update "{'message': {'new_chat_photo': [], 'supergroup_chat_created': False, 'chat': {'last_name': 'help', 'first_name': 'future', 'username': 'imfuturehelp', 'type': 'private', 'id': 503241607}, 'group_chat_created': False, 'date': 1703717208, 'caption_entities': [], 'entities': [{'length': 11, 'offset': 0, 'type': 'bot_command'}], 'photo': [], 'message_id': 163, 'delete_chat_photo': False, 'channel_chat_created': False, 'new_chat_members': [], 'text': '/createtask drew test 10012 [testing testing testing]', 'from': {'language_code': 'en', 'id': 503241607, 'first_name': 'future', 'username': 'imfuturehelp', 'is_bot': False, 'last_name': 'help'}}, 'update_id': 556864838}" caused error "list index out of range"
2023-12-27 17:47:34,752 - INFO - main.py:10 - Bot started!
2023-12-27 17:48:17,818 - INFO - task.py:13 - API Request, create_task
2023-12-27 17:48:18,503 - INFO - api_call.py:29 - API POST request for tasks failed with error 400 Client Error: Bad Request for url: https://dqpllfj7tb.execute-api.us-east-1.amazonaws.com/dev/tasks
2023-12-27 17:49:26,290 - INFO - main.py:10 - Bot started!
2023-12-27 17:49:32,376 - INFO - task.py:13 - API Request, create_task
2023-12-27 17:49:33,116 - INFO - api_call.py:29 - API POST request for tasks failed with error 500 Server Error: Internal Server Error for url: https://dqpllfj7tb.execute-api.us-east-1.amazonaws.com/dev/tasks
2023-12-27 17:52:48,623 - INFO - main.py:10 - Bot started!
2023-12-27 17:53:19,383 - INFO - task.py:13 - API Request, create_task
2023-12-27 17:53:19,951 - INFO - api_call.py:29 - API POST request for tasks failed with error 500 Server Error: Internal Server Error for url: https://dqpllfj7tb.execute-api.us-east-1.amazonaws.com/dev/tasks
2023-12-27 17:54:16,009 - INFO - main.py:10 - Bot started!
2023-12-27 17:54:26,379 - INFO - task.py:13 - API Request, create_task
2023-12-27 17:54:26,969 - INFO - api_call.py:29 - API POST request for tasks failed with error 500 Server Error: Internal Server Error for url: https://dqpllfj7tb.execute-api.us-east-1.amazonaws.com/dev/tasks
2023-12-27 17:56:26,223 - INFO - main.py:10 - Bot started!
2023-12-27 17:56:40,699 - INFO - task.py:13 - API Request, create_task
2023-12-27 18:03:04,867 - INFO - main.py:10 - Bot started!
2023-12-27 18:03:27,803 - INFO - task.py:13 - API Request, create_task
2023-12-27 18:03:30,312 - INFO - api_call.py:29 - API POST request for tasks failed with error 500 Server Error: Internal Server Error for url: https://dqpllfj7tb.execute-api.us-east-1.amazonaws.com/dev/tasks
2023-12-27 18:04:59,734 - INFO - main.py:10 - Bot started!
2023-12-27 18:05:11,420 - INFO - task.py:13 - API Request, create_task
2023-12-27 18:05:12,567 - INFO - api_call.py:29 - API POST request for tasks failed with error 500 Server Error: Internal Server Error for url: https://dqpllfj7tb.execute-api.us-east-1.amazonaws.com/dev/tasks
2023-12-27 18:06:23,866 - INFO - main.py:10 - Bot started!
2023-12-27 18:06:33,578 - INFO - task.py:13 - API Request, create_task
2023-12-27 18:06:34,531 - INFO - api_call.py:29 - API POST request for tasks failed with error 500 Server Error: Internal Server Error for url: https://dqpllfj7tb.execute-api.us-east-1.amazonaws.com/dev/tasks
2023-12-27 18:06:50,825 - INFO - task.py:13 - API Request, create_task
2023-12-27 18:06:59,554 - INFO - main.py:10 - Bot started!
2023-12-27 18:07:08,548 - INFO - task.py:13 - API Request, create_task
2023-12-27 18:07:09,273 - INFO - api_call.py:29 - API POST request for tasks failed with error 500 Server Error: Internal Server Error for url: https://dqpllfj7tb.execute-api.us-east-1.amazonaws.com/dev/tasks
2023-12-27 18:08:07,981 - INFO - main.py:10 - Bot started!
2023-12-27 18:08:22,413 - INFO - task.py:13 - API Request, create_task
2023-12-27 18:08:23,110 - INFO - api_call.py:29 - API POST request for tasks failed with error 500 Server Error: Internal Server Error for url: https://dqpllfj7tb.execute-api.us-east-1.amazonaws.com/dev/tasks
2023-12-27 18:08:41,951 - INFO - main.py:10 - Bot started!
2023-12-27 18:09:01,326 - INFO - task.py:13 - API Request, create_task
2023-12-27 18:09:01,830 - INFO - api_call.py:29 - API POST request for tasks failed with error 500 Server Error: Internal Server Error for url: https://dqpllfj7tb.execute-api.us-east-1.amazonaws.com/dev/tasks
2023-12-27 18:10:58,695 - INFO - main.py:10 - Bot started!
2023-12-27 18:11:19,967 - INFO - task.py:13 - API Request, create_task
2023-12-27 18:11:20,624 - INFO - api_call.py:29 - API POST request for tasks failed with error 500 Server Error: Internal Server Error for url: https://dqpllfj7tb.execute-api.us-east-1.amazonaws.com/dev/tasks
